package skywolf46.commandannotation.v4.test.exceptions

class SecondTestSucceedException : RuntimeException()